Workbook

Sheet README
A1: NUHAS OMAN - CONSOLIDATED CABLE COST MASTER
A2: Built from 99 individual cost sheets. Every figure reconciles to its source sheet.
A4: PURPOSE | B4: A single normalised database behind all 99 cost sheets, so cost can be recalculated from live inputs instead of being frozen inside 99 separate files.
A6: Drivers | B6: LME copper price, OMR/USD rate and margin. Edit here; everything downstream reflows.
A7: Products | B7: One row per cable (99). Cost roll-up is formula-driven from BOM / Operations / Overheads.
A8: BOM | B8: 1,327 material lines. Quantity per km is engineering data; rate is looked up from RM_Rates.
A9: RM_Rates | B9: 133-code material price master. Copper rates are LME-linked (see below); others are fixed.
A10: Operations | B10: Machine hours per product per stage. Cost = hours x cores x machine rate.
A11: Machine_Rates | B11: 34 machines, OMR per machine-hour. Derived from the source sheets (<0.5% variance).
A12: Overheads | B12: 8 overhead lines per product, as entered in the source sheets.
A14: COLOUR KEY | B14: BLUE = hardcoded input you may edit. BLACK = formula. GREEN = link to another sheet. YELLOW = key assumption, confirm before use.
A16: ASSUMPTION 1 | B16: OMR/USD = 0.3845 (Omani rial peg). Source: user-supplied constant, not present in the original sheets. Confirm with Nuhas finance.
A17: ASSUMPTION 2 | B17: Source sheets were all costed at LME = USD 4,850/tonne (stated in cell B3 of every sheet).
A18: ASSUMPTION 3 | B18: Copper rate = (LME x FX / 1000) + drawing premium. The premium per conductor size was derived by subtracting the LME metal value from the rate in the source sheets; it ranges 0.1026-0.1401 OMR/kg and falls as size rises, which is the expected pattern. CONFIRM this decomposition with Nuhas before quoting from it.
... A23: CURRENCY | B23: All values in OMR (Omani Rial) unless stated.

Sheet Drivers
A1: PRICING DRIVERS
A2: Edit the blue cells. Every product cost in this workbook recalculates.
A4: Driver | B4: Value | C4: Note
A5: LME copper (USD/tonne) | B5: 4850 | C5: Live LME cash settlement. Source sheets were built at 4,850.
A6: OMR per USD | B6: 0.3845 | C6: Omani rial peg. Assumption - confirm.
A7: Margin on cost (%) | B7: 0.15 | C7: Illustrative. Set your own quoting margin.
A8: Scrap treatment | B8: as-entered | C8: Scrap qty is stored per BOM line from the source sheets.
A10: Copper metal value (OMR/kg) | B10: =B5*B6/1000 -> 1.864825 | C10: LME x FX / 1000. Drawing premium is added per size in RM_Rates.

Sheet RM_Rates
A1: RAW MATERIAL PRICE MASTER
A2: 133 codes. Verified single-valued across all 99 source sheets.
A4: RM_Code | B4: Description | C4: UOM | D4: LME linked? | E4: Drawing premium (OMR/kg) | F4: Rate (OMR/unit)
A5: ABPT025 | B5: AL-BACKED POLYESTER TAPE 25 MM | C5: KG | D5: no | F5: 1.8359596
A6: ABPT030 | B6: AL-BACKED POLYESTER TAPE 30 MM | C6: KG | D6: no | F6: 1.8359596
A7: ABPT035 | B7: AL-BACKED POLYESTER TAPE 35 MM | C7: KG | D7: no | F7: 1.8359596
A8: ABPT040 | B8: AL-BACKED POLYESTER TAPE 40 MM | C8: KG | D8: no | F8: 1.8359596
A9: ABPT050 | B9: AL-BACKED POLYESTER TAPE 50 MM | C9: KG | D9: no | F9: 1.8359596
A10: ATC180RD | B10: TCA180RD - ANNEALED TINNED COPPER WIRE SIZE- 1.80MM (RE-DRAW) | C10: kg | D10: no | F10: 2.8692296
A11: AWA160 | B11: AL ARMOUR WIRE 1.60 MM DIA | C11: kg | D11: no | F11: 0.9673335
A12: AWA200 | B12: AL ARMOUR WIRE 2.00 MM DIA | C12: kg | D12: no | F12: 0.9673335
A13: AWA250 | B13: AL ARMOUR WIRE 2.50 MM DIA | C13: kg | D13: no | F13: 0.9673335
A14: CC1E | B14: Cu - 1.5 mm2 - Cl 1 - Round | C14: kg | D14: YES | E14: 0.115741 | F14: =Drivers!$B$10+E14 -> 1.980566
A15: CC1F | B15: Cu - 2.5 mm2 - Cl 1 - Round | C15: kg | D15: YES | E15: 0.108407 | F15: =Drivers!$B$10+E15 -> 1.973232
A16: CC2RE07 | B16: Cu - 1.5 mm2 - Cl 2 - Round | C16: kg | D16: YES | E16: 0.125777 | F16: =Drivers!$B$10+E16 -> 1.990602
A17: CC2RF07 | B17: Cu - 2.5 mm2 - Cl 2 - Round | C17: kg | D17: YES | E17: 0.133111 | F17: =Drivers!$B$10+E17 -> 1.997936
A18: CC2RG07 | B18: Cu - 4 mm2 - Cl 2 - Round | C18: kg | D18: YES | E18: 0.138901 | F18: =Drivers!$B$10+E18 -> 2.003726
A19: CC2RH07 | B19: Cu - 6 mm2 - Cl 2 - Round | C19: kg | D19: YES | E19: 0.140059 | F19: =Drivers!$B$10+E19 -> 2.004884
A20: CC2RI07 | B20: Cu - 10 mm2 - Cl 2 - Round | C20: kg | D20: YES | E20: 0.116127 | F20: =Drivers!$B$10+E20 -> 1.980952
A21: CC2RJ07 | B21: Cu - 16 mm2 - Cl 2 - Round | C21: kg | D21: YES | E21: 0.108407 | F21: =Drivers!$B$10+E21 -> 1.973232
A22: CC2RK07 | B22: Cu - 25 mm2 - Cl 2 - Round | C22: kg | D22: YES | E22: 0.106091 | F22: =Drivers!$B$10+E22 -> 1.970916
A23: CC2RL07 | B23: Cu - 35 mm2 - Cl 2 - Round | C23: kg | D23: YES | E23: 0.104547 | F23: =Drivers!$B$10+E23 -> 1.969372
A24: CC2RM07 | B24: Cu - 50 mm2 - Cl 2 - Round | C24: kg | D24: YES | E24: 0.103389 | F24: =Drivers!$B$10+E24 -> 1.968214
A25: CC2RM19 | B25: Cu - 50 mm2 - Cl 2 - Round (19 strands for MV cables) | C25: kg | D25: YES | E25: 0.110337 | F25: =Drivers!$B$10+E25 -> 1.975162
... A52: CC2S4S37 | B52: Cu - 240 mm2 - Cl 2 - 90° Sec | C52: kg | D52: YES | E52: 0.103003 | F52: =Drivers!$B$10+E52 -> 1.967828
A53: CUT3005 | B53: COPPER TAPE 30 X 0.05 MM | C53: kg | D53: no | F53: 3.0084119
A54: CUT4005 | B54: Copper Tape 40 X 0.05 MM | C54: kg | D54: no | F54: 3.0084119
A55: CUT5005 | B55: COPPER TAPE 50 X 0.05 MM | C55: kg | D55: no | F55: 3.0084119
A56: ECAPH010 | B56: END CAP HEAT SHRINKABLE 10 MM | C56: NOS | D56: no | F56: 0.1
A57: ECAPH020 | B57: ECAPH20 - HEAT SHRINKABLE END CAP | C57: NOS | D57: no | F57: 0.12476628
A58: ECAPH030 | B58: END CAP HEAT SHRINKABLE 30 MM | C58: NOS | D58: no | F58: 0.12476628
A59: ECAPH040 | B59: END CAP HEAT SHRINKABLE 40 MM | C59: NOS | D59: no | F59: 0.12476628
A60: ECAPH060 | B60: END CAP HEAT SHRINKABLE 60 MM | C60: NOS | D60: no | F60: 0.25584984
A61: ECAPH080 | B61: END CAP HEAT SHRINKABLE 80 MM | C61: NOS | D61: no | F61: 0.39300001
A62: ECAPH100 | B62: END CAP HEAT SHRINKABLE 100 MM | C62: NOS | D62: no | F62: 0.39300001
A63: ECAPH120 | B63: END CAP HEAT SHRINKABLE 130 MM | C63: NOS | D63: no | F63: 0.5488137
A64: HSF300MM | B64: Heat Shrink Film 300 MM (60micron) | C64: KG | D64: no | F64: 0.67500001
... A137: XSCBON | B137: XLPE SC BONDED COMPOUND | C137: kg | D137: no | F137: 0.82124639

Sheet Machine_Rates
A1: MACHINE HOURLY RATES
A2: Derived as operation cost / machine hour across all sheets. Max variance 0.45%.
A4: Machine_Code | B4: Stage type | C4: Rate (OMR/hr) | D4: Observations | E4: Variance %
A5: ARM-48BN | B5: Armouring | C5: 4.3539 | D5: 14 | E5: 0.019
A6: BNR-L001 | B6: Bunching | C6: 4.129 | D6: 3 | E6: 0
A7: BNR-L002 | B7: Bunching | C7: 4.1332 | D7: 10 | E7: 0.029
A8: BNR-L004 | B8: Bunching | C8: 2.4859 | D8: 14 | E8: 0.095
A9: BNR-N001 | B9: Bunching | C9: 1.716 | D9: 16 | E9: 0.149
A10: BNR-N007 | B10: Bunching | C10: 1.7156 | D10: 6 | E10: 0.451
A11: BNRS1600 | B11: Bunching | C11: 4.1336 | D11: 25 | E11: 0.161
A12: CLR-PS02 | B12: Coiler | C12: 5.1042 | D12: 2 | E12: 0.272
A13: CRW-MP01 | B13: Crosswinding | C13: 4.4599 | D13: 2 | E13: 0.053
A14: CRW-MP02 | B14: Crosswinding | C14: 4.4609 | D14: 1 | E14: 0
A15: DT-2000P | B15: Drum twister / laying up | C15: 12.2442 | D15: 25 | E15: 0.009
A16: DT-3000P | B16: Drum twister / laying up | C16: 16.82 | D16: 32 | E16: 0.006
... A38: VTP-A001 | B38: Vertical taping | C38: 1.771 | D38: 11 | E38: 0.003

Sheet Products
A1: PRODUCT COST MASTER
A2: Cost columns are formulas. Change LME on Drivers and every row reflows.
A4: Product_Code | B4: Description | C4: Family | D4: Standard | E4: Cores | F4: Core unit | G4: Size (mm2) | H4: Conductor | I4: Insulation | J4: Screen | K4: Armour | L4: Sheath | M4: Shape | N4: Voltage | O4: RM cost /km (A) | P4: Operations /km (B) | Q4: Overheads /km (C) | R4: Tooling /km | S4: Total cost /km | T4: Cost /metre | U4: Quote /metre | V4: Source cost /m (orig) | W4: Delta
A5: WJC2VEC4NSL | B5: SC WIRE - BS EN 50525-2-31 - 16 mm2 - Cu(2) - PVC - (Yellow-green) - 450/750V | C5: SC WIRE | D5: BS EN 50525-2-31 | E5: 1 | F5: core | G5: 16 | H5: Cu | I5: PVC | L5: PVC | N5: 450/750V | O5: =SUM(BOM!$J$5:$J$12) -> 296.20312 | P5: =SUM(Operations!$G$5:$G$7) -> 2.8740882 | Q5: =SUM(Overheads!$D$5:$D$12)-R5 -> 11.636 | R5: 0.033 | S5: =O5+P5+Q5+R5 -> 310.74621 | T5: =S5/1000 -> 0.31074621 | U5: =T5*(1+Drivers!$B$7) -> 0.35735814 | V5: 0.31074712 | W5: =T5-V5 -> -9.1603464e-07
A6: WKC2VEC4NSL | B6: SC WIRE - BS EN 50525-2-31 - 25 mm2 - Cu(2) - PVC - (Yellow-green) - 450/750V | C6: SC WIRE | D6: BS EN 50525-2-31 | E6: 1 | F6: core | G6: 25 | H6: Cu | I6: PVC | L6: PVC | N6: 450/750V | O6: =SUM(BOM!$J$13:$J$20) -> 461.57742 | P6: =SUM(Operations!$G$8:$G$10) -> 2.991149 | Q6: =SUM(Overheads!$D$13:$D$20)-R6 -> 18.036 | R6: 0.033 | S6: =O6+P6+Q6+R6 -> 482.63757 | T6: =S6/1000 -> 0.48263757 | U6: =T6*(1+Drivers!$B$7) -> 0.5550332 | V6: 0.48263642 | W6: =T6-V6 -> 1.1418487e-06
A7: WLC2VEC4NSL | B7: SC WIRE - BS EN 50525-2-31 - 35 mm2 - Cu(2) - PVC - (Yellow-green) - 450/750V | C7: SC WIRE | D7: BS EN 50525-2-31 | E7: 1 | F7: core | G7: 35 | H7: Cu | I7: PVC | L7: PVC | N7: 450/750V | O7: =SUM(BOM!$J$21:$J$28) -> 634.94497 | P7: =SUM(Operations!$G$11:$G$13) -> 2.9521881 | Q7: =SUM(Overheads!$D$21:$D$28)-R7 -> 24.766 | R7: 0.033 | S7: =O7+P7+Q7+R7 -> 662.69616 | T7: =S7/1000 -> 0.66269616 | U7: =T7*(1+Drivers!$B$7) -> 0.76210058 | V7: 0.66269598 | W7: =T7-V7 -> 1.7775854e-07
A8: WMC2VEC4 | B8: SC WIRE - BS EN 50525-2-31 - 50 mm2 - Cu(2) - PVC - (Yellow-green) - 450/750V | C8: SC WIRE | D8: BS EN 50525-2-31 | E8: 1 | F8: core | G8: 50 | H8: Cu | I8: PVC | L8: PVC | N8: 450/750V | O8: =SUM(BOM!$J$29:$J$36) -> 854.42807 | P8: =SUM(Operations!$G$14:$G$16) -> 3.4212215 | Q8: =SUM(Overheads!$D$29:$D$36)-R8 -> 33.344 | R8: 0.033 | S8: =O8+P8+Q8+R8 -> 891.22629 | T8: =S8/1000 -> 0.89122629 | U8: =T8*(1+Drivers!$B$7) -> 1.0249102 | V8: 0.89122608 | W8: =T8-V8 -> 2.0709938e-07
A9: CC2RN19NSL | B9: Cu - 70 mm2 - Cl 2 - Round | C9: BARE CONDUCTOR | E9: 1 | F9: core | G9: 70 | H9: Cu | M9: Round | O9: =SUM(BOM!$J$37:$J$41) -> 1187.71 | P9: =SUM(Operations!$G$17:$G$19) -> 2.6848668 | Q9: =SUM(Overheads!$D$37:$D$44)-R9 -> 49.137001 | R9: 10 | S9: =O9+P9+Q9+R9 -> 1249.5318 | T9: =S9/1000 -> 1.2495318 | U9: =T9*(1+Drivers!$B$7) -> 1.4369616 | V9: 1.249532 | W9: =T9-V9 -> -1.5270942e-07
A10: WOC2VEC4 | B10: SC WIRE - BS EN 50525-2-31 - 95 mm2 - Cu(2) - PVC - (Yellow-green) - 450/750V | C10: SC WIRE | D10: BS EN 50525-2-31 | E10: 1 | F10: core | G10: 95 | H10: Cu | I10: PVC | L10: PVC | N10: 450/750V | O10: =SUM(BOM!$J$42:$J$49) -> 1696.4531 | P10: =SUM(Operations!$G$20:$G$22) -> 16.924729 | Q10: =SUM(Overheads!$D$45:$D$52)-R10 -> 69.797999 | R10: 0.033 | S10: =O10+P10+Q10+R10 -> 1783.2088 | T10: =S10/1000 -> 1.7832088 | U10: =T10*(1+Drivers!$B$7) -> 2.0506902 | V10: 1.7832081 | W10: =T10-V10 -> 7.0045206e-07
A11: WIC2VEC4NSL | B11: SC WIRE - BS EN 50525-2-31 - 10 mm2 - Cu(2) - PVC - (Yellow-green) - 450/750V | C11: SC WIRE | D11: BS EN 50525-2-31 | E11: 1 | F11: core | G11: 10 | H11: Cu | I11: PVC | L11: PVC | N11: 450/750V | O11: =SUM(BOM!$J$50:$J$57) -> 194.70662 | P11: =SUM(Operations!$G$23:$G$25) -> 1.8814826 | Q11: =SUM(Overheads!$D$53:$D$60)-R11 -> 7.4020001 | R11: 0.033 | S11: =O11+P11+Q11+R11 -> 204.0231 | T11: =S11/1000 -> 0.2040231 | U11: =T11*(1+Drivers!$B$7) -> 0.23462656 | V11: 0.20402362 | W11: =T11-V11 -> -5.1951162e-07
A12: IEC1XP10AATWTKNA | B12: INSTRU CABLE - BS EN 50288-7 - 10Pair x 1.5 mm2 - Cu(1) - XLPE (KW) - IOSCR - FRRT PVC - SWA - FRRT PVC - 500V | C12: INSTRU CABLE | D12: BS EN 50288-7 | E12: 10 | F12: pair | G12: 1.5 | H12: Cu | I12: XLPE | J12: IOSCR | K12: SWA | L12: FRRT PVC | N12: 500V | O12: =SUM(BOM!$J$58:$J$75) -> 1289.919 | P12: =SUM(Operations!$G$26:$G$33) -> 130.80833 | Q12: =SUM(Overheads!$D$61:$D$68)-R12 -> 61.323999 | R12: 10 | S12: =O12+P12+Q12+R12 -> 1492.0513 | T12: =S12/1000 -> 1.4920513 | U12: =T12*(1+Drivers!$B$7) -> 1.715859 | V12: 1.4920462 | W12: =T12-V12 -> 5.123845e-06
A13: IEC1XP10AATWTKNM | B13: INSTRU CABLE - BS EN 50288-7 - 10Pair x 1.5 mm2 - Cu(1) - MGT - XLPE (KW) - IOSCR - FRRT PVC - SWA - FRRT PVC - 500V | C13: INSTRU CABLE | D13: BS EN 50288-7 | E13: 10 | F13: pair | G13: 1.5 | H13: Cu | I13: XLPE | J13: IOSCR | K13: SWA | L13: FRRT PVC | N13: 500V | O13: =SUM(BOM!$J$76:$J$94) -> 1843.7554 | P13: =SUM(Operations!$G$34:$G$42) -> 218.85324 | Q13: =SUM(Overheads!$D$69:$D$76)-R13 -> 72.258 | R13: 10 | S13: =O13+P13+Q13+R13 -> 2144.8666 | T13: =S13/1000 -> 2.1448666 | U13: =T13*(1+Drivers!$B$7) -> 2.4665966 | V13: 2.144863 | W13: =T13-V13 -> 3.634645e-06
A14: IFC1XP10AATWTKNA | B14: INSTRU CABLE - BS EN 50288-7 - 10Pair x 2.5 mm2 - Cu(1) - XLPE (KW) - IOSCR - FRRT PVC - SWA - FRRT PVC - 500V | C14: INSTRU CABLE | D14: BS EN 50288-7 | E14: 10 | F14: pair | G14: 2.5 | H14: Cu | I14: XLPE | J14: IOSCR | K14: SWA | L14: FRRT PVC | N14: 500V | O14: =SUM(BOM!$J$95:$J$113) -> 1853.7429 | P14: =SUM(Operations!$G$43:$G$50) -> 121.39838 | Q14: =SUM(Overheads!$D$77:$D$84)-R14 -> 75.424 | R14: 10 | S14: =O14+P14+Q14+R14 -> 2060.5653 | T14: =S14/1000 -> 2.0605653 | U14: =T14*(1+Drivers!$B$7) -> 2.3696501 | V14: 2.0605699 | W14: =T14-V14 -> -4.6325595e-06
A15: CC2RP19NSL | B15: Cu - 120 mm2 - Cl 2 - Round | C15: BARE CONDUCTOR | E15: 1 | F15: core | G15: 120 | H15: Cu | M15: Round | O15: =SUM(BOM!$J$114:$J$118) -> 2075.0824 | P15: =SUM(Operations!$G$51:$G$53) -> 13.656462 | Q15: =SUM(Overheads!$D$85:$D$92)-R15 -> 88.562999 | R15: 10 | S15: =O15+P15+Q15+R15 -> 2187.3019 | T15: =S15/1000 -> 2.1873019 | U15: =T15*(1+Drivers!$B$7) -> 2.5153972 | V15: 2.1873025 | W15: =T15-V15 -> -5.748473e-07
A16: C07C12F2XLLWLKNA | B16: CONTROL CABLE - IEC 60502-1 - 12Cx2.5 mm2 - Cu(2) - XLPE (White)-OSCR- LSOH - SWA - LSOH - Round - 1kV | C16: CONTROL CABLE | D16: IEC 60502-1 | E16: 12 | F16: core | G16: 2.5 | H16: Cu | I16: XLPE | J16: OSCR | K16: SWA | L16: LSOH | M16: Round | N16: 1kV | O16: =SUM(BOM!$J$119:$J$133) -> 980.07797 | P16: =SUM(Operations!$G$54:$G$62) -> 86.181437 | Q16: =SUM(Overheads!$D$93:$D$100)-R16 -> 49.058 | R16: 10 | S16: =O16+P16+Q16+R16 -> 1125.3174 | T16: =S16/1000 -> 1.1253174 | U16: =T16*(1+Drivers!$B$7) -> 1.294115 | V16: 1.1253173 | W16: =T16-V16 -> 1.5433375e-07
A17: C07C12F2XLLWLKNB | B17: CONTROL CABLE - IEC 60502-1 - 12Cx2.5 mm2 - Cu(2) - MGT - XLPE (White) - OSCR - LSOH - SWA - LSOH - Round - 1kV | C17: CONTROL CABLE | D17: IEC 60502-1 | E17: 12 | F17: core | G17: 2.5 | H17: Cu | I17: XLPE | J17: OSCR | K17: SWA | L17: LSOH | M17: Round | N17: 1kV | O17: =SUM(BOM!$J$134:$J$149) -> 1375.2962 | P17: =SUM(Operations!$G$63:$G$72) -> 142.05076 | Q17: =SUM(Overheads!$D$101:$D$108)-R17 -> 57.333 | R17: 10 | S17: =O17+P17+Q17+R17 -> 1584.6799 | T17: =S17/1000 -> 1.5846799 | U17: =T17*(1+Drivers!$B$7) -> 1.8223819 | V17: 1.5846813 | W17: =T17-V17 -> -1.3595862e-06
A18: P37CR1S2XLVAVKNN | B18: LV CABLE - IEC 60502-1 - 1Cx240 mm2 - Cu(2) - XLPE (Black) - PVC - AWA - PVC - Round - 1kV | C18: LV CABLE | D18: IEC 60502-1 | E18: 1 | F18: core | G18: 240 | H18: Cu | I18: XLPE | K18: AWA | L18: PVC | M18: Round | N18: 1kV | O18: =SUM(BOM!$J$150:$J$159) -> 4611.9651 | P18: =SUM(Operations!$G$73:$G$78) -> 98.158978 | Q18: =SUM(Overheads!$D$109:$D$116)-R18 -> 201.283 | R18: 1 | S18: =O18+P18+Q18+R18 -> 4912.4071 | T18: =S18/1000 -> 4.9124071 | U18: =T18*(1+Drivers!$B$7) -> 5.6492682 | V18: 4.9124072 | W18: =T18-V18 -> -9.5535446e-08
A19: P61CR1T2XLVAVKNN | B19: LV CABLE - IEC 60502-1 - 1Cx300 mm2 - Cu(2) - XLPE (Black) - PVC - AWA - PVC - Round - 1kV | C19: LV CABLE | D19: IEC 60502-1 | E19: 1 | F19: core | G19: 300 | H19: Cu | I19: XLPE | K19: AWA | L19: PVC | M19: Round | N19: 1kV | O19: =SUM(BOM!$J$160:$J$169) -> 5717.5934 | P19: =SUM(Operations!$G$79:$G$84) -> 130.88772 | Q19: =SUM(Overheads!$D$117:$D$124)-R19 -> 253.431 | R19: 1 | S19: =O19+P19+Q19+R19 -> 6102.9121 | T19: =S19/1000 -> 6.1029121 | U19: =T19*(1+Drivers!$B$7) -> 7.018349 | V19: 6.1029105 | W19: =T19-V19 -> 1.6315251e-06
A20: P61CR1U2XLVAVKNN | B20: LV CABLE - IEC 60502-1 - 1Cx400 mm2 - Cu(2) - XLPE (Black) - PVC - AWA - PVC - Round - 1kV | C20: LV CABLE | D20: IEC 60502-1 | E20: 1 | F20: core | G20: 400 | H20: Cu | I20: XLPE | K20: AWA | L20: PVC | M20: Round | N20: 1kV | O20: =SUM(BOM!$J$170:$J$179) -> 7349.8625 | P20: =SUM(Operations!$G$85:$G$90) -> 150.67796 | Q20: =SUM(Overheads!$D$125:$D$132)-R20 -> 319.68699 | R20: 1 | S20: =O20+P20+Q20+R20 -> 7821.2275 | T20: =S20/1000 -> 7.8212275 | U20: =T20*(1+Drivers!$B$7) -> 8.9944116 | V20: 7.8212276 | W20: =T20-V20 -> -1.5626824e-07
A21: P61CR1W2XLVAVKNN | B21: LV CABLE - IEC 60502-1 - 1Cx630 mm2 - Cu(2) - XLPE (Black) - PVC - AWA - PVC - Round - 1kV | C21: LV CABLE | D21: IEC 60502-1 | E21: 1 | F21: core | G21: 630 | H21: Cu | I21: XLPE | K21: AWA | L21: PVC | M21: Round | N21: 1kV | O21: =SUM(BOM!$J$180:$J$189) -> 12016.356 | P21: =SUM(Operations!$G$91:$G$96) -> 177.26458 | Q21: =SUM(Overheads!$D$133:$D$140)-R21 -> 510.02301 | R21: 1 | S21: =O21+P21+Q21+R21 -> 12704.643 | T21: =S21/1000 -> 12.704643 | U21: =T21*(1+Drivers!$B$7) -> 14.61034 | V21: 12.704642 | W21: =T21-V21 -> 1.381072e-06
A22: MCU1XLBJ5MVAVKNN | B22: MV CABLE - IEC 60502-2 - 1Cx400 mm2 - Cu - XLPE (Natural) - CTS - PVC - AWA - PVC (Black) - 30kV | C22: MV CABLE | D22: IEC 60502-2 | E22: 1 | F22: core | G22: 400 | H22: Cu | I22: XLPE | J22: CTS | K22: AWA | L22: PVC | N22: 30kV | O22: =SUM(BOM!$J$190:$J$202) -> 8879.096 | P22: =SUM(Operations!$G$97:$G$104) -> 359.85601 | Q22: =SUM(Overheads!$D$141:$D$148)-R22 -> 396.135 | R22: 5 | S22: =O22+P22+Q22+R22 -> 9640.087 | T22: =S22/1000 -> 9.640087 | U22: =T22*(1+Drivers!$B$7) -> 11.0861 | V22: 9.6400901 | W22: =T22-V22 -> -3.1074682e-06
A23: MCW1XLBJ5MVAVKNN | B23: MV CABLE - IEC 60502-2 - 1Cx630 mm2 - Cu - XLPE (Natural) - CTS - PVC - AWA - PVC (Black) - 30kV | C23: MV CABLE | D23: IEC 60502-2 | E23: 1 | F23: core | G23: 630 | H23: Cu | I23: XLPE | J23: CTS | K23: AWA | L23: PVC | N23: 30kV | O23: =SUM(BOM!$J$203:$J$215) -> 13705.115 | P23: =SUM(Operations!$G$105:$G$112) -> 450.2021 | Q23: =SUM(Overheads!$D$149:$D$156)-R23 -> 605.197 | R23: 5 | S23: =O23+P23+Q23+R23 -> 14765.514 | T23: =S23/1000 -> 14.765514 | U23: =T23*(1+Drivers!$B$7) -> 16.980341 | V23: 14.765515 | W23: =T23-V23 -> -1.0976279e-06
A24: IEC1XP01NATWTKNA | B24: INSTRU CABLE - BS EN 50288-7 - 1Pair x 1.5 mm2 - Cu(1) - XLPE (KW) - OSCR - FRRT PVC - SWA - FRRT PVC - 500V | C24: INSTRU CABLE | D24: BS EN 50288-7 | E24: 1 | F24: pair | G24: 1.5 | H24: Cu | I24: XLPE | J24: OSCR | K24: SWA | L24: FRRT PVC | N24: 500V | O24: =SUM(BOM!$J$216:$J$231) -> 201.38992 | P24: =SUM(Operations!$G$113:$G$119) -> 30.242751 | Q24: =SUM(Overheads!$D$157:$D$164)-R24 -> 12.639 | R24: 10 | S24: =O24+P24+Q24+R24 -> 254.27167 | T24: =S24/1000 -> 0.25427167 | U24: =T24*(1+Drivers!$B$7) -> 0.29241243 | V24: 0.25427192 | W24: =T24-V24 -> -2.4924751e-07
A25: IEC1XP01NATWTKNM | B25: INSTRU CABLE - BS EN 50288-7 - 1Pair x 1.5 mm2 - Cu(1) - MGT - XLPE (KW) - OSCR - FRRT PVC - SWA - FRRT PVC - 500V | C25: INSTRU CABLE | D25: BS EN 50288-7 | E25: 1 | F25: pair | G25: 1.5 | H25: Cu | I25: XLPE | J25: OSCR | K25: SWA | L25: FRRT PVC | N25: 500V | O25: =SUM(BOM!$J$232:$J$248) -> 271.38685 | P25: =SUM(Operations!$G$120:$G$127) -> 38.874605 | Q25: =SUM(Overheads!$D$165:$D$172)-R25 -> 13.811 | R25: 10 | S25: =O25+P25+Q25+R25 -> 334.07245 | T25: =S25/1000 -> 0.33407245 | U25: =T25*(1+Drivers!$B$7) -> 0.38418332 | V25: 0.33407285 | W25: =T25-V25 -> -3.9524751e-07
A26: WPC2VEC4 | B26: SC WIRE - BS EN 50525-2-31 - 120 mm2 - Cu(2) - PVC - (Yellow-green) - 450/750V | C26: SC WIRE | D26: BS EN 50525-2-31 | E26: 1 | F26: core | G26: 120 | H26: Cu | I26: PVC | L26: PVC | N26: 450/750V | O26: =SUM(BOM!$J$249:$J$256) -> 2142.7899 | P26: =SUM(Operations!$G$128:$G$130) -> 16.191849 | Q26: =SUM(Overheads!$D$173:$D$180)-R26 -> 86.727 | R26: 0.033 | S26: =O26+P26+Q26+R26 -> 2245.7417 | T26: =S26/1000 -> 2.2457417 | U26: =T26*(1+Drivers!$B$7) -> 2.582603 | V26: 2.2457419 | W26: =T26-V26 -> -1.8794731e-07
A27: MCU1XLBH5MVAVKNN | B27: MV CABLE - IEC 60502-2 - 1Cx400 mm2 - Cu - XLPE (Natural) - CTS - PVC - AWA - PVC (Black) - 15kV | C27: MV CABLE | D27: IEC 60502-2 | E27: 1 | F27: core | G27: 400 | H27: Cu | I27: XLPE | J27: CTS | K27: AWA | L27: PVC | N27: 15kV | O27: =SUM(BOM!$J$257:$J$268) -> 8332.6981 | P27: =SUM(Operations!$G$131:$G$138) -> 346.90254 | Q27: =SUM(Overheads!$D$181:$D$188)-R27 -> 383.09399 | R27: 5 | S27: =O27+P27+Q27+R27 -> 9067.6946 | T27: =S27/1000 -> 9.0676946 | U27: =T27*(1+Drivers!$B$7) -> 10.427849 | V27: 9.0676962 | W27: =T27-V27 -> -1.5759682e-06
A28: MCW1XLBH5MVAVKNN | B28: MV CABLE - IEC 60502-2 - 1Cx630 mm2 - Cu - XLPE (Natural) - CTS - PVC - AWA - PVC (Black) - 15kV | C28: MV CABLE | D28: IEC 60502-2 | E28: 1 | F28: core | G28: 630 | H28: Cu | I28: XLPE | J28: CTS | K28: AWA | L28: PVC | N28: 15kV | O28: =SUM(BOM!$J$269:$J$281) -> 13019.161 | P28: =SUM(Operations!$G$139:$G$146) -> 360.56886 | Q28: =SUM(Overheads!$D$189:$D$196)-R28 -> 566.934 | R28: 5 | S28: =O28+P28+Q28+R28 -> 13951.664 | T28: =S28/1000 -> 13.951664 | U28: =T28*(1+Drivers!$B$7) -> 16.044414 | V28: 13.951665 | W28: =T28-V28 -> -1.342328e-06
A29: MCW1XLBF5MVAVKNN | B29: MV CABLE - IEC 60502-2 - 1Cx630 mm2 - Cu - XLPE (Natural) - CTS - PVC - AWA - PVC (Black) - 6kV | C29: MV CABLE | D29: IEC 60502-2 | E29: 1 | F29: core | G29: 630 | H29: Cu | I29: XLPE | J29: CTS | K29: AWA | L29: PVC | N29: 6kV | O29: =SUM(BOM!$J$282:$J$294) -> 12791.005 | P29: =SUM(Operations!$G$147:$G$154) -> 296.32014 | Q29: =SUM(Overheads!$D$197:$D$204)-R29 -> 551.358 | R29: 5 | S29: =O29+P29+Q29+R29 -> 13643.683 | T29: =S29/1000 -> 13.643683 | U29: =T29*(1+Drivers!$B$7) -> 15.690236 | V29: 13.643683 | W29: =T29-V29 -> -5.562795e-08
A30: WFC2VEC4Y1 | B30: SC WIRE - BS EN 50525-2-31 - 2.5 mm2 - Cu(2) - PVC - (Yellow-green) - 450/750V - Coil | C30: SC WIRE | D30: BS EN 50525-2-31 | E30: 1 | F30: core | G30: 2.5 | H30: Cu | I30: PVC | L30: PVC | N30: 450/750V | O30: =SUM(BOM!$J$295:$J$302) -> 48.193591 | P30: =SUM(Operations!$G$155:$G$159) -> 1.0243575 | Q30: =SUM(Overheads!$D$205:$D$212)-R30 -> 1.517 | R30: 0.033 | S30: =O30+P30+Q30+R30 -> 50.767948 | T30: =S30/1000 -> 0.050767948 | U30: =T30*(1+Drivers!$B$7) -> 0.05838314 | V30: 0.050767591 | W30: =T30-V30 -> 3.5727821e-07
A31: IEC1XP20AATWTKNM | B31: INSTRU CABLE - BS EN 50288-7 - 20Pair x 1.5 mm2 - Cu(1) - MGT - XLPE (KW) - IOSCR - FRRT PVC - SWA - FRRT PVC - 500V | C31: INSTRU CABLE | D31: BS EN 50288-7 | E31: 20 | F31: pair | G31: 1.5 | H31: Cu | I31: XLPE | J31: IOSCR | K31: SWA | L31: FRRT PVC | N31: 500V | O31: =SUM(BOM!$J$303:$J$320) -> 3345.6673 | P31: =SUM(Operations!$G$160:$G$168) -> 324.79154 | Q31: =SUM(Overheads!$D$213:$D$220)-R31 -> 110.632 | R31: 10 | S31: =O31+P31+Q31+R31 -> 3791.0908 | T31: =S31/1000 -> 3.7910908 | U31: =T31*(1+Drivers!$B$7) -> 4.3597544 | V31: 3.7910831 | W31: =T31-V31 -> 7.7224846e-06
A32: IEC1XP20AATWTKNA | B32: INSTRU CABLE - BS EN 50288-7 - 20Pair x 1.5 mm2 - Cu(1) - XLPE (KW) - IOSCR - FRRT PVC - SWA - FRRT PVC - 500V | C32: INSTRU CABLE | D32: BS EN 50288-7 | E32: 20 | F32: pair | G32: 1.5 | H32: Cu | I32: XLPE | J32: IOSCR | K32: SWA | L32: FRRT PVC | N32: 500V | O32: =SUM(BOM!$J$321:$J$339) -> 2337.1591 | P32: =SUM(Operations!$G$169:$G$176) -> 150.6486 | Q32: =SUM(Overheads!$D$221:$D$228)-R32 -> 92.818 | R32: 10 | S32: =O32+P32+Q32+R32 -> 2590.6257 | T32: =S32/1000 -> 2.5906257 | U32: =T32*(1+Drivers!$B$7) -> 2.9792196 | V32: 2.5906148 | W32: =T32-V32 -> 1.0990085e-05
A33: IFC1XP20AATWTKNA | B33: INSTRU CABLE - BS EN 50288-7 - 20Pair x 2.5 mm2 - Cu(1) - XLPE (KW) - IOSCR - FRRT PVC - SWA - FRRT PVC - 500V | C33: INSTRU CABLE | D33: BS EN 50288-7 | E33: 20 | F33: pair | G33: 2.5 | H33: Cu | I33: XLPE | J33: IOSCR | K33: SWA | L33: FRRT PVC | N33: 500V | O33: =SUM(BOM!$J$340:$J$357) -> 3290.5383 | P33: =SUM(Operations!$G$177:$G$184) -> 173.96949 | Q33: =SUM(Overheads!$D$229:$D$236)-R33 -> 125.485 | R33: 10 | S33: =O33+P33+Q33+R33 -> 3599.9928 | T33: =S33/1000 -> 3.5999928 | U33: =T33*(1+Drivers!$B$7) -> 4.1399917 | V33: 3.6000004 | W33: =T33-V33 -> -7.5420158e-06
A34: C07C24E2XLLWLKNA | B34: CONTROL CABLE - IEC 60502-1 - 24Cx1.5 mm2 - Cu(2) - XLPE (White)-OSCR- LSOH - SWA - LSOH - Round - 1kV | C34: CONTROL CABLE | D34: IEC 60502-1 | E34: 24 | F34: core | G34: 1.5 | H34: Cu | I34: XLPE | J34: OSCR | K34: SWA | L34: LSOH | M34: Round | N34: 1kV | O34: =SUM(BOM!$J$358:$J$372) -> 1253.6616 | P34: =SUM(Operations!$G$185:$G$193) -> 100.91006 | Q34: =SUM(Overheads!$D$237:$D$244)-R34 -> 59.776999 | R34: 10 | S34: =O34+P34+Q34+R34 -> 1424.3487 | T34: =S34/1000 -> 1.4243487 | U34: =T34*(1+Drivers!$B$7) -> 1.638001 | V34: 1.4243469 | W34: =T34-V34 -> 1.7796809e-06
A35: C07C24F2XLLWLKNA | B35: CONTROL CABLE - IEC 60502-1 - 24Cx2.5 mm2 - Cu(2) - XLPE (White)-OSCR- LSOH - SWA - LSOH - Round - 1kV | C35: CONTROL CABLE | D35: IEC 60502-1 | E35: 24 | F35: core | G35: 2.5 | H35: Cu | I35: XLPE | J35: OSCR | K35: SWA | L35: LSOH | M35: Round | N35: 1kV | O35: =SUM(BOM!$J$373:$J$387) -> 1767.7614 | P35: =SUM(Operations!$G$194:$G$202) -> 106.31813 | Q35: =SUM(Overheads!$D$245:$D$252)-R35 -> 79.536 | R35: 10 | S35: =O35+P35+Q35+R35 -> 1963.6155 | T35: =S35/1000 -> 1.9636155 | U35: =T35*(1+Drivers!$B$7) -> 2.2581578 | V35: 1.9636172 | W35: =T35-V35 -> -1.7186483e-06
A36: C07C24F2XLLWLKNB | B36: CONTROL CABLE - IEC 60502-1 - 24Cx2.5 mm2 - Cu(2) - MGT - XLPE (White)- OSCR - LSOH - SWA - LSOH - Round - 1kV | C36: CONTROL CABLE | D36: IEC 60502-1 | E36: 24 | F36: core | G36: 2.5 | H36: Cu | I36: XLPE | J36: OSCR | K36: SWA | L36: LSOH | M36: Round | N36: 1kV | O36: =SUM(BOM!$J$388:$J$403) -> 2530.3144 | P36: =SUM(Operations!$G$203:$G$212) -> 221.78033 | Q36: =SUM(Overheads!$D$253:$D$260)-R36 -> 95.109 | R36: 10 | S36: =O36+P36+Q36+R36 -> 2857.2037 | T36: =S36/1000 -> 2.8572037 | U36: =T36*(1+Drivers!$B$7) -> 3.2857843 | V36: 2.8572068 | W36: =T36-V36 -> -3.0327083e-06
A37: C07C24E2XLLWLKNB | B37: CONTROL CABLE - IEC 60502-1 - 24Cx1.5 mm2 - Cu(2) - MGT - XLPE (White)- OSCR - LSOH - SWA - LSOH - Round - 1kV | C37: CONTROL CABLE | D37: IEC 60502-1 | E37: 24 | F37: core | G37: 1.5 | H37: Cu | I37: XLPE | J37: OSCR | K37: SWA | L37: LSOH | M37: Round | N37: 1kV | O37: =SUM(BOM!$J$404:$J$419) -> 1928.8249 | P37: =SUM(Operations!$G$213:$G$222) -> 240.43573 | Q37: =SUM(Overheads!$D$261:$D$268)-R37 -> 72.701999 | R37: 10 | S37: =O37+P37+Q37+R37 -> 2251.9626 | T37: =S37/1000 -> 2.2519626 | U37: =T37*(1+Drivers!$B$7) -> 2.589757 | V37: 2.2519597 | W37: =T37-V37 -> 2.9285208e-06
A38: C07C02F2XLLWLKNA | B38: CONTROL CABLE - IEC 60502-1 - 2Cx2.5 mm2 - Cu(2) - XLPE (White) - OSCR - LSOH - SWA - LSOH - Round - 1kV | C38: CONTROL CABLE | D38: IEC 60502-1 | E38: 2 | F38: core | G38: 2.5 | H38: Cu | I38: XLPE | J38: OSCR | K38: SWA | L38: LSOH | M38: Round | N38: 1kV | O38: =SUM(BOM!$J$420:$J$434) -> 285.93541 | P38: =SUM(Operations!$G$223:$G$231) -> 32.577084 | Q38: =SUM(Overheads!$D$269:$D$276)-R38 -> 14.566 | R38: 10 | S38: =O38+P38+Q38+R38 -> 343.07849 | T38: =S38/1000 -> 0.34307849 | U38: =T38*(1+Drivers!$B$7) -> 0.39454027 | V38: 0.34307738 | W38: =T38-V38 -> 1.11374e-06
A39: C07C02F2XLLWLKNB | B39: CONTROL CABLE - IEC 60502-1 - 2Cx2.5 mm2 - Cu(2) - MGT - XLPE (White) - OSCR - LSOH - SWA - LSOH - Round - 1kV | C39: CONTROL CABLE | D39: IEC 60502-1 | E39: 2 | F39: core | G39: 2.5 | H39: Cu | I39: XLPE | J39: OSCR | K39: SWA | L39: LSOH | M39: Round | N39: 1kV | O39: =SUM(BOM!$J$435:$J$450) -> 354.80993 | P39: =SUM(Operations!$G$232:$G$241) -> 37.170252 | Q39: =SUM(Overheads!$D$277:$D$284)-R39 -> 16.55 | R39: 10 | S39: =O39+P39+Q39+R39 -> 418.53019 | T39: =S39/1000 -> 0.41853019 | U39: =T39*(1+Drivers!$B$7) -> 0.48130971 | V39: 0.41853006 | W39: =T39-V39 -> 1.2191e-07
A40: IEC1XP02AATWTKNA | B40: INSTRU CABLE - BS EN 50288-7 - 2Pair x 1.5 mm2 - Cu(1) - XLPE (KW) - IOSCR - FRRT PVC - SWA - FRRT PVC - 500V | C40: INSTRU CABLE | D40: BS EN 50288-7 | E40: 2 | F40: pair | G40: 1.5 | H40: Cu | I40: XLPE | J40: IOSCR | K40: SWA | L40: FRRT PVC | N40: 500V | O40: =SUM(BOM!$J$451:$J$470) -> 406.65994 | P40: =SUM(Operations!$G$242:$G$249) -> 34.640899 | Q40: =SUM(Overheads!$D$285:$D$292)-R40 -> 20.069 | R40: 10 | S40: =O40+P40+Q40+R40 -> 471.36984 | T40: =S40/1000 -> 0.47136984 | U40: =T40*(1+Drivers!$B$7) -> 0.54207531 | V40: 0.47136786 | W40: =T40-V40 -> 1.9775373e-06
A41: MCM3XLBF5MVWVKNN | B41: MV CABLE - IEC 60502-2 - 3Cx50 mm2 - Cu - XLPE (RYB) - CTS - PVC - SWA - PVC (Black) - 6kV | C41: MV CABLE | D41: IEC 60502-2 | E41: 3 | F41: core | G41: 50 | H41: Cu | I41: XLPE | J41: CTS | K41: SWA | L41: PVC | N41: 6kV | O41: =SUM(BOM!$J$471:$J$483) -> 4127.7883 | P41: =SUM(Operations!$G$250:$G$257) -> 181.38812 | Q41: =SUM(Overheads!$D$293:$D$300)-R41 -> 170.366 | R41: 5 | S41: =O41+P41+Q41+R41 -> 4484.5424 | T41: =S41/1000 -> 4.4845424 | U41: =T41*(1+Drivers!$B$7) -> 5.1572238 | V41: 4.4845413 | W41: =T41-V41 -> 1.0807106e-06
...

Sheet BOM
A1: BILL OF MATERIALS
A2: Quantity per km is engineering data. Rate is looked up from RM_Rates.
A4: Product_Code | B4: Sheet | C4: RM_Code | D4: Description | E4: UOM | F4: Qty /km | G4: Scrap qty | H4: Total qty | I4: Rate (OMR) | J4: Value (OMR)
A5: WJC2VEC4NSL | B5: 1 x 16 Cost Sheet - WJC2VEC4NSL | C5: CC2RJ07 | D5: Cu - 16 mm2 - Cl 2 - Round | E5: kg | F5: 136.5 | G5: 0.68300003 | H5: =F5+G5 -> 137.183 | I5: =INDEX(RM_Rates!$F$5:$F$137,MATCH(C5,RM_Rates!$A$5:$A$137,0)) -> 1.973232 | J5: =H5*I5 -> 270.69389
A6: WJC2VEC4NSL | B6: 1 x 16 Cost Sheet - WJC2VEC4NSL | C6: PVCTI1 | D6: PVC TI-1 NATURAL | E6: KG | F6: 30.6 | G6: 0.61199999 | H6: =F6+G6 -> 31.212 | I6: =INDEX(RM_Rates!$F$5:$F$137,MATCH(C6,RM_Rates!$A$5:$A$137,0)) -> 0.40272659 | J6: =H6*I6 -> 12.569902
A7: WJC2VEC4NSL | B7: 1 x 16 Cost Sheet - WJC2VEC4NSL | C7: PVCMBY | D7: PVC MB YELLOW | E7: KG | F7: 0.3213 | G7: 0.0060000001 | H7: =F7+G7 -> 0.3273 | I7: =INDEX(RM_Rates!$F$5:$F$137,MATCH(C7,RM_Rates!$A$5:$A$137,0)) -> 1.452 | J7: =H7*I7 -> 0.47523961
A8: WJC2VEC4NSL | B8: 1 x 16 Cost Sheet - WJC2VEC4NSL | C8: PVCMBGR | D8: PVC MB GREEN | E8: KG | F8: 0.13770001 | G8: 0.003 | H8: =F8+G8 -> 0.14070001 | I8: =INDEX(RM_Rates!$F$5:$F$137,MATCH(C8,RM_Rates!$A$5:$A$137,0)) -> 1.452 | J8: =H8*I8 -> 0.20429641
A9: WJC2VEC4NSL | B9: 1 x 16 Cost Sheet - WJC2VEC4NSL | C9: WD700450575 | D9: WD700 X 450 X 575 MM | E9: NOS | F9: 1 | G9: 0 | H9: =F9+G9 -> 1 | I9: =INDEX(RM_Rates!$F$5:$F$137,MATCH(C9,RM_Rates!$A$5:$A$137,0)) -> 8.8836746 | J9: =H9*I9 -> 8.8836746
A10: WJC2VEC4NSL | B10: 1 x 16 Cost Sheet - WJC2VEC4NSL | C10: ECAPH010 | D10: END CAP HEAT SHRINKABLE 10 MM | E10: NOS | F10: 2 | G10: 0 | H10: =F10+G10 -> 2 | I10: =INDEX(RM_Rates!$F$5:$F$137,MATCH(C10,RM_Rates!$A$5:$A$137,0)) -> 0.1 | J10: =H10*I10 -> 0.2
A11: WJC2VEC4NSL | B11: 1 x 16 Cost Sheet - WJC2VEC4NSL | C11: WRP570 | D11: DRUM WRAPPER 570 MM | E11: m | F11: 2.2 | G11: 0 | H11: =F11+G11 -> 2.2 | I11: =INDEX(RM_Rates!$F$5:$F$137,MATCH(C11,RM_Rates!$A$5:$A$137,0)) -> 1.4075208 | J11: =H11*I11 -> 3.0965458
A12: WJC2VEC4NSL | B12: 1 x 16 Cost Sheet - WJC2VEC4NSL | C12: LLDPE | D12: BLACK LLDPE SHEET (WIDTH - 1050 MM) | E12: KG | F12: 0.14 | G12: 0 | H12: =F12+G12 -> 0.14 | I12: =INDEX(RM_Rates!$F$5:$F$137,MATCH(C12,RM_Rates!$A$5:$A$137,0)) -> 0.56840003 | J12: =H12*I12 -> 0.079576004
A13: WKC2VEC4NSL | B13: 1 x 25 Cost Sheet - WKC2VEC4NSL | C13: CC2RK07 | D13: Cu - 25 mm2 - Cl 2 - Round | E13: kg | F13: 217 | G13: 1.085 | H13: =F13+G13 -> 218.085 | I13: =INDEX(RM_Rates!$F$5:$F$137,MATCH(C13,RM_Rates!$A$5:$A$137,0)) -> 1.970916 | J13: =H13*I13 -> 429.82722
A14: WKC2VEC4NSL | B14: 1 x 25 Cost Sheet - WKC2VEC4NSL | C14: PVCTI1 | D14: PVC TI-1 NATURAL | E14: KG | F14: 44.900002 | G14: 0.898 | H14: =F14+G14 -> 45.798002 | I14: =INDEX(RM_Rates!$F$5:$F$137,MATCH(C14,RM_Rates!$A$5:$A$137,0)) -> 0.40272659 | J14: =H14*I14 -> 18.444073
A15: WKC2VEC4NSL | B15: 1 x 25 Cost Sheet - WKC2VEC4NSL | C15: PVCMBY | D15: PVC MB YELLOW | E15: KG | F15: 0.47145 | G15: 0.0089999996 | H15: =F15+G15 -> 0.48045 | I15: =INDEX(RM_Rates!$F$5:$F$137,MATCH(C15,RM_Rates!$A$5:$A$137,0)) -> 1.452 | J15: =H15*I15 -> 0.69761341
A16: WKC2VEC4NSL | B16: 1 x 25 Cost Sheet - WKC2VEC4NSL | C16: PVCMBGR | D16: PVC MB GREEN | E16: KG | F16: 0.20205 | G16: 0.0040000002 | H16: =F16+G16 -> 0.20605 | I16: =INDEX(RM_Rates!$F$5:$F$137,MATCH(C16,RM_Rates!$A$5:$A$137,0)) -> 1.452 | J16: =H16*I16 -> 0.29918461
... A1331: CC2RO19NSL | B1331: 95 sq.mm Cost Sheet - CC2RO19NSL | C1331: LLDPE | D1331: BLACK LLDPE SHEET (WIDTH - 1050 MM) | E1331: KG | F1331: 0.16 | G1331: 0 | H1331: =F1331+G1331 -> 0.16 | I1331: =INDEX(RM_Rates!$F$5:$F$137,MATCH(C1331,RM_Rates!$A$5:$A$137,0)) -> 0.56840003 | J1331: =H1331*I1331 -> 0.090944002

Sheet Operations
A1: MANUFACTURING OPERATIONS
A2: Cost = machine hours x cores x machine rate.
A4: Product_Code | B4: Sheet | C4: Machine_Code | D4: Machine hours | E4: Cores | F4: Rate (OMR/hr) | G4: Cost (OMR/km)
A5: WJC2VEC4NSL | B5: 1 x 16 Cost Sheet - WJC2VEC4NSL | C5: RBD-TWD1 | D5: 0.827 | E5: 1 | F5: =INDEX(Machine_Rates!$C$5:$C$38,MATCH(C5,Machine_Rates!$A$5:$A$38,0)) -> 0 | G5: =D5*E5*F5 -> 0
A6: WJC2VEC4NSL | B6: 1 x 16 Cost Sheet - WJC2VEC4NSL | C6: BNRS1600 | D6: 0.289 | E6: 1 | F6: =INDEX(Machine_Rates!$C$5:$C$38,MATCH(C6,Machine_Rates!$A$5:$A$38,0)) -> 4.1336 | G6: =D6*E6*F6 -> 1.1946104
A7: WJC2VEC4NSL | B7: 1 x 16 Cost Sheet - WJC2VEC4NSL | C7: EX-90R1 | D7: 0.154 | E7: 1 | F7: =INDEX(Machine_Rates!$C$5:$C$38,MATCH(C7,Machine_Rates!$A$5:$A$38,0)) -> 10.9057 | G7: =D7*E7*F7 -> 1.6794778
A8: WKC2VEC4NSL | B8: 1 x 25 Cost Sheet - WKC2VEC4NSL | C8: RBD-TWD1 | D8: 1.102 | E8: 1 | F8: =INDEX(Machine_Rates!$C$5:$C$38,MATCH(C8,Machine_Rates!$A$5:$A$38,0)) -> 0 | G8: =D8*E8*F8 -> 0
A9: WKC2VEC4NSL | B9: 1 x 25 Cost Sheet - WKC2VEC4NSL | C9: BNRS1600 | D9: 0.254 | E9: 1 | F9: =INDEX(Machine_Rates!$C$5:$C$38,MATCH(C9,Machine_Rates!$A$5:$A$38,0)) -> 4.1336 | G9: =D9*E9*F9 -> 1.0499344
A10: WKC2VEC4NSL | B10: 1 x 25 Cost Sheet - WKC2VEC4NSL | C10: EX-90R1 | D10: 0.178 | E10: 1 | F10: =INDEX(Machine_Rates!$C$5:$C$38,MATCH(C10,Machine_Rates!$A$5:$A$38,0)) -> 10.9057 | G10: =D10*E10*F10 -> 1.9412146
A11: WLC2VEC4NSL | B11: 1 x 35Cost Sheet - WLC2VEC4NSL | C11: RBD-TWD2 | D11: 1.102 | E11: 1 | F11: =INDEX(Machine_Rates!$C$5:$C$38,MATCH(C11,Machine_Rates!$A$5:$A$38,0)) -> 0 | G11: =D11*E11*F11 -> 0
A12: WLC2VEC4NSL | B12: 1 x 35Cost Sheet - WLC2VEC4NSL | C12: BNRS1600 | D12: 0.205 | E12: 1 | F12: =INDEX(Machine_Rates!$C$5:$C$38,MATCH(C12,Machine_Rates!$A$5:$A$38,0)) -> 4.1336 | G12: =D12*E12*F12 -> 0.847388
A13: WLC2VEC4NSL | B13: 1 x 35Cost Sheet - WLC2VEC4NSL | C13: EX-90R1 | D13: 0.193 | E13: 1 | F13: =INDEX(Machine_Rates!$C$5:$C$38,MATCH(C13,Machine_Rates!$A$5:$A$38,0)) -> 10.9057 | G13: =D13*E13*F13 -> 2.1048001
A14: WMC2VEC4 | B14: 1 x 50Cost Sheet - WMC2VEC4 | C14: RBD-TWD1 | D14: 2.179 | E14: 1 | F14: =INDEX(Machine_Rates!$C$5:$C$38,MATCH(C14,Machine_Rates!$A$5:$A$38,0)) -> 0 | G14: =D14*E14*F14 -> 0
A15: WMC2VEC4 | B15: 1 x 50Cost Sheet - WMC2VEC4 | C15: BNRS1600 | D15: 0.176 | E15: 1 | F15: =INDEX(Machine_Rates!$C$5:$C$38,MATCH(C15,Machine_Rates!$A$5:$A$38,0)) -> 4.1336 | G15: =D15*E15*F15 -> 0.7275136
A16: WMC2VEC4 | B16: 1 x 50Cost Sheet - WMC2VEC4 | C16: EX-90R1 | D16: 0.247 | E16: 1 | F16: =INDEX(Machine_Rates!$C$5:$C$38,MATCH(C16,Machine_Rates!$A$5:$A$38,0)) -> 10.9057 | G16: =D16*E16*F16 -> 2.6937079
... A732: CC2RO19NSL | B732: 95 sq.mm Cost Sheet - CC2RO19NSL | C732: CRW-MP01 | D732: 0.514 | E732: 1 | F732: =INDEX(Machine_Rates!$C$5:$C$38,MATCH(C732,Machine_Rates!$A$5:$A$38,0)) -> 4.4599 | G732: =D732*E732*F732 -> 2.2923886

Sheet Overheads
A1: OVERHEAD ALLOCATION
A2: Stored per product as entered in the source sheets - not formula-derived.
A4: Product_Code | B4: Sheet | C4: Overhead line | D4: Value (OMR/km)
A5: WJC2VEC4NSL | B5: 1 x 16 Cost Sheet - WJC2VEC4NSL | C5: Admin-Salaries | D5: 2.0309999
A6: WJC2VEC4NSL | B6: 1 x 16 Cost Sheet - WJC2VEC4NSL | C6: Admin Overheads | D6: 1.67
A7: WJC2VEC4NSL | B7: 1 x 16 Cost Sheet - WJC2VEC4NSL | C7: Marketing Salary | D7: 0.95599997
A8: WJC2VEC4NSL | B8: 1 x 16 Cost Sheet - WJC2VEC4NSL | C8: Mktg Expenses | D8: 1.147
A9: WJC2VEC4NSL | B9: 1 x 16 Cost Sheet - WJC2VEC4NSL | C9: Interest-Fixed Assets | D9: 0.65799999
A10: WJC2VEC4NSL | B10: 1 x 16 Cost Sheet - WJC2VEC4NSL | C10: Interest-Working Capital | D10: 1.935
A11: WJC2VEC4NSL | B11: 1 x 16 Cost Sheet - WJC2VEC4NSL | C11: Common Wages Prodn | D11: 3.2390001
A12: WJC2VEC4NSL | B12: 1 x 16 Cost Sheet - WJC2VEC4NSL | C12: Cost of tooling | D12: 0.033
A13: WKC2VEC4NSL | B13: 1 x 25 Cost Sheet - WKC2VEC4NSL | C13: Admin-Salaries | D13: 3.2290001
A14: WKC2VEC4NSL | B14: 1 x 25 Cost Sheet - WKC2VEC4NSL | C14: Admin Overheads | D14: 2.655
A15: WKC2VEC4NSL | B15: 1 x 25 Cost Sheet - WKC2VEC4NSL | C15: Marketing Salary | D15: 1.5190001
A16: WKC2VEC4NSL | B16: 1 x 25 Cost Sheet - WKC2VEC4NSL | C16: Mktg Expenses | D16: 1.823
... A796: CC2RO19NSL | B796: 95 sq.mm Cost Sheet - CC2RO19NSL | C796: Cost of tooling | D796: 10
